2024-12-06 22:37:18,886 - INFO - Calling make_erro with args: (2, 0) and kwargs: {}
2024-12-06 22:37:18,886 - ERROR - Error in make_erro: division by zero
Traceback (most recent call last):
  File "c:\Users\Носир\OneDrive\Документы\coding folder\python\git\items_manipulation\item_control_jun\logs\logger.py", line 17, in wrapper
    result = func(*args, **kwargs)
  File "c:\Users\Носир\OneDrive\Документы\coding folder\python\git\items_manipulation\item_control_jun\main.py", line 8, in make_erro
    return a/b
ZeroDivisionError: division by zero
2024-12-06 23:24:23,801 - INFO - Calling create_user with args: ('test', 'test') and kwargs: {}
2024-12-06 23:24:23,801 - INFO - create_user returned: None
2024-12-06 23:24:46,335 - INFO - Calling create_user with args: ('test', 'test') and kwargs: {}
2024-12-06 23:24:46,335 - INFO - create_user returned: None
2024-12-06 23:25:48,422 - INFO - Calling create_user with args: ('test', 'test') and kwargs: {}
2024-12-06 23:25:48,422 - INFO - create_user returned: None
2024-12-06 23:25:59,122 - INFO - Calling create_user with args: ('test', 'test') and kwargs: {}
2024-12-06 23:25:59,122 - INFO - create_user returned: None
2024-12-06 23:26:28,731 - INFO - Calling create_user with args: ('test', 'test') and kwargs: {}
2024-12-06 23:26:28,731 - ERROR - Error in create_user: unable to open database file
Traceback (most recent call last):
  File "C:\Users\Носир\OneDrive\Документы\coding folder\python\git\items_manipulation\item_control_jun\logger.py", line 17, in wrapper
    result = func(*args, **kwargs)
  File "C:\Users\Носир\OneDrive\Документы\coding folder\python\git\items_manipulation\item_control_jun\auth.py", line 20, in create_user
    return connection_db(query)
  File "C:\Users\Носир\OneDrive\Документы\coding folder\python\git\items_manipulation\item_control_jun\utils.py", line 16, in connection_db
    conn = sqlite3.connect('database/data.db')
sqlite3.OperationalError: unable to open database file
2024-12-06 23:27:18,166 - INFO - Calling create_user with args: ('test', 'test') and kwargs: {}
2024-12-06 23:27:18,167 - ERROR - Error in create_user: table users has 3 columns but 2 values were supplied
Traceback (most recent call last):
  File "C:\Users\Носир\OneDrive\Документы\coding folder\python\git\items_manipulation\item_control_jun\logger.py", line 17, in wrapper
    result = func(*args, **kwargs)
  File "C:\Users\Носир\OneDrive\Документы\coding folder\python\git\items_manipulation\item_control_jun\auth.py", line 20, in create_user
    return connection_db(query)
  File "C:\Users\Носир\OneDrive\Документы\coding folder\python\git\items_manipulation\item_control_jun\utils.py", line 18, in connection_db
    result = cursor.execute(query)
sqlite3.OperationalError: table users has 3 columns but 2 values were supplied
2024-12-06 23:28:25,587 - INFO - Calling create_user with args: ('test', 'test') and kwargs: {}
2024-12-06 23:28:25,588 - INFO - create_user returned: <sqlite3.Cursor object at 0x0000022D6DCEA840>
2024-12-06 23:28:59,263 - INFO - Calling create_user with args: ('test', 'test') and kwargs: {}
2024-12-06 23:28:59,267 - ERROR - Error in create_user: UNIQUE constraint failed: users.username
Traceback (most recent call last):
  File "C:\Users\Носир\OneDrive\Документы\coding folder\python\git\items_manipulation\item_control_jun\logger.py", line 17, in wrapper
    result = func(*args, **kwargs)
  File "C:\Users\Носир\OneDrive\Документы\coding folder\python\git\items_manipulation\item_control_jun\auth.py", line 20, in create_user
    return connection_db(query)
  File "C:\Users\Носир\OneDrive\Документы\coding folder\python\git\items_manipulation\item_control_jun\utils.py", line 18, in connection_db
    result = cursor.execute(query)
sqlite3.IntegrityError: UNIQUE constraint failed: users.username
2024-12-06 23:29:53,272 - INFO - Calling create_user with args: ('test', 'test') and kwargs: {}
2024-12-06 23:29:53,272 - INFO - create_user returned: None
2024-12-06 23:29:58,661 - INFO - Calling create_user with args: ('test2', 'test') and kwargs: {}
2024-12-06 23:29:58,676 - INFO - create_user returned: <sqlite3.Cursor object at 0x000001F6B70CA840>
2024-12-06 23:32:19,129 - INFO - Calling get_user with args: ('asdf',) and kwargs: {}
2024-12-06 23:32:19,129 - ERROR - Error in get_user: no such column: asdf
Traceback (most recent call last):
  File "C:\Users\Носир\OneDrive\Документы\coding folder\python\git\items_manipulation\item_control_jun\logger.py", line 17, in wrapper
    result = func(*args, **kwargs)
  File "C:\Users\Носир\OneDrive\Документы\coding folder\python\git\items_manipulation\item_control_jun\auth.py", line 13, in get_user
    return connection_db(query).fetchone()
  File "C:\Users\Носир\OneDrive\Документы\coding folder\python\git\items_manipulation\item_control_jun\utils.py", line 18, in connection_db
    result = cursor.execute(query)
sqlite3.OperationalError: no such column: asdf
2024-12-06 23:32:57,769 - INFO - Calling get_user with args: ('asdf',) and kwargs: {}
2024-12-06 23:32:57,769 - INFO - get_user returned: None
2024-12-06 23:33:04,533 - INFO - Calling get_user with args: ('test',) and kwargs: {}
2024-12-06 23:33:04,533 - INFO - get_user returned: None
2024-12-06 23:33:14,456 - INFO - Calling get_user with args: ('test',) and kwargs: {}
2024-12-06 23:33:14,456 - INFO - get_user returned: None
2024-12-06 23:33:29,824 - INFO - Calling get_user with args: ('test2',) and kwargs: {}
2024-12-06 23:33:29,824 - INFO - get_user returned: None
2024-12-06 23:34:28,738 - INFO - Calling get_user with args: ('test2',) and kwargs: {}
2024-12-06 23:34:28,738 - INFO - get_user returned: None
2024-12-06 23:35:13,377 - INFO - Calling get_user with args: ('test2',) and kwargs: {}
2024-12-06 23:35:13,377 - INFO - get_user returned: <sqlite3.Cursor object at 0x000002CC027CA840>
2024-12-06 23:35:20,643 - INFO - Calling get_user with args: ('test2',) and kwargs: {}
2024-12-06 23:35:20,643 - INFO - get_user returned: None
2024-12-06 23:35:39,361 - INFO - Calling get_user with args: ('test2',) and kwargs: {}
2024-12-06 23:35:39,361 - INFO - get_user returned: None
2024-12-06 23:35:48,878 - INFO - Calling get_user with args: ('test2',) and kwargs: {}
2024-12-06 23:35:48,878 - ERROR - Error in get_user: Cannot operate on a closed database.
Traceback (most recent call last):
  File "C:\Users\Носир\OneDrive\Документы\coding folder\python\git\items_manipulation\item_control_jun\logger.py", line 17, in wrapper
    result = func(*args, **kwargs)
  File "C:\Users\Носир\OneDrive\Документы\coding folder\python\git\items_manipulation\item_control_jun\auth.py", line 14, in get_user
    print(result.fetchall())
sqlite3.ProgrammingError: Cannot operate on a closed database.
2024-12-06 23:36:21,500 - INFO - Calling get_user with args: ('test2',) and kwargs: {}
2024-12-06 23:36:21,500 - INFO - get_user returned: None
2024-12-06 23:36:40,888 - INFO - Calling get_user with args: ('asdf',) and kwargs: {}
2024-12-06 23:36:40,890 - INFO - get_user returned: []
2024-12-06 23:36:47,537 - INFO - Calling get_user with args: ('test',) and kwargs: {}
2024-12-06 23:36:47,537 - INFO - get_user returned: [(1, 'test', 'test')]
2024-12-06 23:36:55,731 - INFO - Calling get_user with args: ('test',) and kwargs: {}
2024-12-06 23:36:55,731 - INFO - get_user returned: (1, 'test', 'test')
2024-12-06 23:39:57,935 - INFO - Calling get_user with args: ('test2',) and kwargs: {}
2024-12-06 23:39:57,935 - INFO - Calling connection_db with args: ("\n    select * from users where username='test2'\n    limit 1\n    ",) and kwargs: {}
2024-12-06 23:39:57,936 - INFO - connection_db returned: [(2, 'test2', 'e455578dcb1f00b67cb6eb19a7b6b4a140f42869fd8790c603f1d38ab7fd578c')]
2024-12-06 23:39:57,936 - INFO - get_user returned: (2, 'test2', 'e455578dcb1f00b67cb6eb19a7b6b4a140f42869fd8790c603f1d38ab7fd578c')
2024-12-06 23:39:57,936 - INFO - Calling hash_maker with args: ('test',) and kwargs: {}
2024-12-06 23:39:57,936 - INFO - hash_maker returned: e455578dcb1f00b67cb6eb19a7b6b4a140f42869fd8790c603f1d38ab7fd578c
2024-12-06 23:43:23,783 - INFO - Calling get_user with args: ('Nosir',) and kwargs: {}
2024-12-06 23:43:23,784 - INFO - Calling connection_db with args: ("\n    select * from users where username='Nosir'\n    limit 1\n    ",) and kwargs: {}
2024-12-06 23:43:23,788 - INFO - connection_db returned: []
2024-12-06 23:43:23,789 - INFO - get_user returned: None
2024-12-06 23:44:09,949 - INFO - Calling get_user with args: ('Nosir',) and kwargs: {}
2024-12-06 23:44:09,950 - INFO - Calling connection_db with args: ("\n    select * from users where username='Nosir'\n    limit 1\n    ",) and kwargs: {}
2024-12-06 23:44:09,954 - INFO - connection_db returned: []
2024-12-06 23:44:09,954 - INFO - get_user returned: None
2024-12-06 23:45:16,877 - INFO - Calling get_user with args: ('asdf',) and kwargs: {}
2024-12-06 23:45:16,877 - INFO - Calling connection_db with args: ("\n    select * from users where username='asdf'\n    limit 1\n    ",) and kwargs: {}
2024-12-06 23:45:16,877 - INFO - connection_db returned: []
2024-12-06 23:45:16,877 - INFO - get_user returned: None
2024-12-06 23:52:44,876 - INFO - Calling get_user with args: ('from os import system',) and kwargs: {}
2024-12-06 23:52:44,877 - INFO - Calling connection_db with args: ("\n    select * from users where username='from os import system'\n    limit 1\n    ",) and kwargs: {}
2024-12-06 23:52:44,935 - INFO - connection_db returned: []
2024-12-06 23:52:44,936 - INFO - get_user returned: None
2024-12-06 23:52:44,944 - INFO - Calling get_user with args: ('def clean_console():',) and kwargs: {}
2024-12-06 23:52:44,944 - INFO - Calling connection_db with args: ("\n    select * from users where username='def clean_console():'\n    limit 1\n    ",) and kwargs: {}
2024-12-06 23:52:44,945 - INFO - connection_db returned: []
2024-12-06 23:52:44,945 - INFO - get_user returned: None
2024-12-06 23:52:51,119 - INFO - Calling get_user with args: ('Nosir',) and kwargs: {}
2024-12-06 23:52:51,120 - INFO - Calling connection_db with args: ("\n    select * from users where username='Nosir'\n    limit 1\n    ",) and kwargs: {}
2024-12-06 23:52:51,124 - INFO - connection_db returned: []
2024-12-06 23:52:51,125 - INFO - get_user returned: None
2024-12-06 23:53:33,019 - INFO - Calling get_user with args: ('Nosir',) and kwargs: {}
2024-12-06 23:53:33,021 - INFO - Calling connection_db with args: ("\n    select * from users where username='Nosir'\n    limit 1\n    ",) and kwargs: {}
2024-12-06 23:53:33,024 - INFO - connection_db returned: []
2024-12-06 23:53:33,025 - INFO - get_user returned: None
2024-12-06 23:53:49,162 - INFO - Calling get_user with args: ('Nosir',) and kwargs: {}
2024-12-06 23:53:49,162 - INFO - Calling connection_db with args: ("\n    select * from users where username='Nosir'\n    limit 1\n    ",) and kwargs: {}
2024-12-06 23:53:49,166 - INFO - connection_db returned: []
2024-12-06 23:53:49,166 - INFO - get_user returned: None
2024-12-06 23:53:49,168 - INFO - Calling clean_console with args: () and kwargs: {}
2024-12-06 23:53:49,234 - INFO - clean_console returned: None
2024-12-06 23:54:19,653 - INFO - Calling get_user with args: ('Nosir',) and kwargs: {}
2024-12-06 23:54:19,653 - INFO - Calling connection_db with args: ("\n    select * from users where username='Nosir'\n    limit 1\n    ",) and kwargs: {}
2024-12-06 23:54:19,655 - INFO - connection_db returned: []
2024-12-06 23:54:19,655 - INFO - get_user returned: None
2024-12-06 23:54:19,655 - INFO - Calling clean_console with args: () and kwargs: {}
2024-12-06 23:54:19,667 - INFO - clean_console returned: None
2024-12-06 23:54:21,814 - INFO - Calling clean_console with args: () and kwargs: {}
2024-12-06 23:54:21,860 - INFO - clean_console returned: None
2024-12-06 23:54:35,293 - INFO - Calling get_user with args: ('test2',) and kwargs: {}
2024-12-06 23:54:35,293 - INFO - Calling connection_db with args: ("\n    select * from users where username='test2'\n    limit 1\n    ",) and kwargs: {}
2024-12-06 23:54:35,293 - INFO - connection_db returned: [(2, 'test2', 'e455578dcb1f00b67cb6eb19a7b6b4a140f42869fd8790c603f1d38ab7fd578c')]
2024-12-06 23:54:35,293 - INFO - get_user returned: (2, 'test2', 'e455578dcb1f00b67cb6eb19a7b6b4a140f42869fd8790c603f1d38ab7fd578c')
2024-12-07 00:02:58,017 - INFO - Calling get_user with args: ('test2',) and kwargs: {}
2024-12-07 00:02:58,017 - INFO - Calling connection_db with args: ("\n    select * from users where username='test2'\n    limit 1\n    ",) and kwargs: {}
2024-12-07 00:02:58,017 - INFO - connection_db returned: [(2, 'test2', 'e455578dcb1f00b67cb6eb19a7b6b4a140f42869fd8790c603f1d38ab7fd578c')]
2024-12-07 00:02:58,017 - INFO - get_user returned: (2, 'test2', 'e455578dcb1f00b67cb6eb19a7b6b4a140f42869fd8790c603f1d38ab7fd578c')
2024-12-07 00:02:59,614 - INFO - Calling get_access with args: ('test2', 'test') and kwargs: {}
2024-12-07 00:02:59,614 - INFO - Calling get_user with args: ('test2',) and kwargs: {}
2024-12-07 00:02:59,614 - INFO - Calling connection_db with args: ("\n    select * from users where username='test2'\n    limit 1\n    ",) and kwargs: {}
2024-12-07 00:02:59,614 - INFO - connection_db returned: [(2, 'test2', 'e455578dcb1f00b67cb6eb19a7b6b4a140f42869fd8790c603f1d38ab7fd578c')]
2024-12-07 00:02:59,614 - INFO - get_user returned: (2, 'test2', 'e455578dcb1f00b67cb6eb19a7b6b4a140f42869fd8790c603f1d38ab7fd578c')
2024-12-07 00:02:59,614 - INFO - Calling hash_maker with args: ('test',) and kwargs: {}
2024-12-07 00:02:59,614 - INFO - hash_maker returned: e455578dcb1f00b67cb6eb19a7b6b4a140f42869fd8790c603f1d38ab7fd578c
2024-12-07 00:02:59,614 - INFO - get_access returned: True
2024-12-07 00:12:29,531 - ERROR - Error in connection_db: UNIQUE constraint failed: items.name
Traceback (most recent call last):
  File "C:\Users\Носир\OneDrive\Документы\coding folder\python\git\items_manipulation\item_control_jun\logger.py", line 18, in wrapper
    result = func(*args, **kwargs)
  File "C:\Users\Носир\OneDrive\Документы\coding folder\python\git\items_manipulation\item_control_jun\utils.py", line 22, in connection_db
    result = cursor.execute(query).fetchall()
sqlite3.IntegrityError: UNIQUE constraint failed: items.name
2024-12-07 00:13:13,540 - ERROR - Error in connection_db: UNIQUE constraint failed: items.name
Traceback (most recent call last):
  File "C:\Users\Носир\OneDrive\Документы\coding folder\python\git\items_manipulation\item_control_jun\logger.py", line 18, in wrapper
    result = func(*args, **kwargs)
  File "C:\Users\Носир\OneDrive\Документы\coding folder\python\git\items_manipulation\item_control_jun\utils.py", line 22, in connection_db
    result = cursor.execute(query).fetchall()
sqlite3.IntegrityError: UNIQUE constraint failed: items.name
2024-12-07 00:28:48,320 - ERROR - Error in clean_console: system() takes 0 positional arguments but 1 was given
Traceback (most recent call last):
  File "C:\Users\Носир\OneDrive\Документы\coding folder\python\git\items_manipulation\item_control_jun\logger.py", line 18, in wrapper
    result = func(*args, **kwargs)
  File "C:\Users\Носир\OneDrive\Документы\coding folder\python\git\items_manipulation\item_control_jun\utils.py", line 32, in clean_console
    system('cls')
TypeError: system() takes 0 positional arguments but 1 was given
2024-12-07 00:28:48,320 - ERROR - Error in main: system() takes 0 positional arguments but 1 was given
Traceback (most recent call last):
  File "C:\Users\Носир\OneDrive\Документы\coding folder\python\git\items_manipulation\item_control_jun\logger.py", line 18, in wrapper
    result = func(*args, **kwargs)
  File "C:\Users\Носир\OneDrive\Документы\coding folder\python\git\items_manipulation\item_control_jun\main.py", line 32, in main
    clean_console()
  File "C:\Users\Носир\OneDrive\Документы\coding folder\python\git\items_manipulation\item_control_jun\logger.py", line 18, in wrapper
    result = func(*args, **kwargs)
  File "C:\Users\Носир\OneDrive\Документы\coding folder\python\git\items_manipulation\item_control_jun\utils.py", line 32, in clean_console
    system('cls')
TypeError: system() takes 0 positional arguments but 1 was given
2024-12-07 00:39:23,018 - ERROR - Error in main: 'str' object has no attribute 'isfloat'
Traceback (most recent call last):
  File "C:\Users\Носир\OneDrive\Документы\coding folder\python\git\items_manipulation\item_control_jun\logger.py", line 18, in wrapper
    result = func(*args, **kwargs)
  File "C:\Users\Носир\OneDrive\Документы\coding folder\python\git\items_manipulation\item_control_jun\main.py", line 45, in main
    if item_price.isfloat() or item_price.isdigit():
AttributeError: 'str' object has no attribute 'isfloat'
2024-12-07 00:52:50,030 - ERROR - Error in connection_db: UNIQUE constraint failed: items.name
Traceback (most recent call last):
  File "C:\Users\Носир\OneDrive\Документы\coding folder\python\git\items_manipulation\item_control_jun\logger.py", line 18, in wrapper
    result = func(*args, **kwargs)
  File "C:\Users\Носир\OneDrive\Документы\coding folder\python\git\items_manipulation\item_control_jun\utils.py", line 23, in connection_db
    result = cursor.execute(query).fetchall()
sqlite3.IntegrityError: UNIQUE constraint failed: items.name
2024-12-07 00:57:09,742 - ERROR - Error in main: list index out of range
Traceback (most recent call last):
  File "C:\Users\Носир\OneDrive\Документы\coding folder\python\git\items_manipulation\item_control_jun\logger.py", line 18, in wrapper
    result = func(*args, **kwargs)
  File "C:\Users\Носир\OneDrive\Документы\coding folder\python\git\items_manipulation\item_control_jun\main.py", line 47, in main
    item_get_once = get_item_by_name(item_name)
  File "C:\Users\Носир\OneDrive\Документы\coding folder\python\git\items_manipulation\item_control_jun\crud.py", line 24, in get_item_by_name
    return connection_db(query)[0]
IndexError: list index out of range
2024-12-07 00:57:47,286 - ERROR - Error in main: list index out of range
Traceback (most recent call last):
  File "C:\Users\Носир\OneDrive\Документы\coding folder\python\git\items_manipulation\item_control_jun\logger.py", line 18, in wrapper
    result = func(*args, **kwargs)
  File "C:\Users\Носир\OneDrive\Документы\coding folder\python\git\items_manipulation\item_control_jun\main.py", line 47, in main
    item_get_once = get_item_by_name(item_name)
  File "C:\Users\Носир\OneDrive\Документы\coding folder\python\git\items_manipulation\item_control_jun\crud.py", line 24, in get_item_by_name
    return connection_db(query)[0]
IndexError: list index out of range
2024-12-07 01:07:35,141 - ERROR - Error in connection_db: UNIQUE constraint failed: items.name
Traceback (most recent call last):
  File "C:\Users\Носир\OneDrive\Документы\coding folder\python\git\items_manipulation\item_control_jun\logger.py", line 18, in wrapper
    result = func(*args, **kwargs)
  File "C:\Users\Носир\OneDrive\Документы\coding folder\python\git\items_manipulation\item_control_jun\utils.py", line 23, in connection_db
    result = cursor.execute(query).fetchall()
sqlite3.IntegrityError: UNIQUE constraint failed: items.name
2024-12-07 01:08:32,737 - ERROR - Error in main: 'NoneType' object is not iterable
Traceback (most recent call last):
  File "C:\Users\Носир\OneDrive\Документы\coding folder\python\git\items_manipulation\item_control_jun\logger.py", line 18, in wrapper
    result = func(*args, **kwargs)
  File "C:\Users\Носир\OneDrive\Документы\coding folder\python\git\items_manipulation\item_control_jun\main.py", line 69, in main
    for k in get_all_items():
TypeError: 'NoneType' object is not iterable
2024-12-07 01:22:45,284 - ERROR - Error in main: Invalid value for header. Must be True or False.
Traceback (most recent call last):
  File "C:\Users\Носир\OneDrive\Документы\coding folder\python\git\items_manipulation\item_control_jun\myvenv\lib\site-packages\prettytable\prettytable.py", line 627, in _validate_true_or_false
    assert val in (True, False)
AssertionError

During handling of the above exception, another exception occurred:

Traceback (most recent call last):
  File "C:\Users\Носир\OneDrive\Документы\coding folder\python\git\items_manipulation\item_control_jun\logger.py", line 18, in wrapper
    result = func(*args, **kwargs)
  File "C:\Users\Носир\OneDrive\Документы\coding folder\python\git\items_manipulation\item_control_jun\main.py", line 71, in main
    table.header = [('id', 'name', 'slug', 'price',
  File "C:\Users\Носир\OneDrive\Документы\coding folder\python\git\items_manipulation\item_control_jun\myvenv\lib\site-packages\prettytable\prettytable.py", line 986, in header
    self._validate_option("header", val)
  File "C:\Users\Носир\OneDrive\Документы\coding folder\python\git\items_manipulation\item_control_jun\myvenv\lib\site-packages\prettytable\prettytable.py", line 534, in _validate_option
    self._validate_true_or_false(option, val)
  File "C:\Users\Носир\OneDrive\Документы\coding folder\python\git\items_manipulation\item_control_jun\myvenv\lib\site-packages\prettytable\prettytable.py", line 630, in _validate_true_or_false
    raise ValueError(msg)
ValueError: Invalid value for header. Must be True or False.
2024-12-07 01:24:34,864 - ERROR - Error in main: Invalid value for header. Must be True or False.
Traceback (most recent call last):
  File "c:\Users\Носир\OneDrive\Документы\coding folder\python\git\items_manipulation\item_control_jun\myvenv\lib\site-packages\prettytable\prettytable.py", line 627, in _validate_true_or_false
    assert val in (True, False)
AssertionError

During handling of the above exception, another exception occurred:

Traceback (most recent call last):
  File "C:\Users\Носир\OneDrive\Документы\coding folder\python\git\items_manipulation\item_control_jun\logger.py", line 18, in wrapper
    result = func(*args, **kwargs)
  File "C:\Users\Носир\OneDrive\Документы\coding folder\python\git\items_manipulation\item_control_jun\main.py", line 71, in main
    table.header = [('id', 'name', 'slug', 'price',
  File "c:\Users\Носир\OneDrive\Документы\coding folder\python\git\items_manipulation\item_control_jun\myvenv\lib\site-packages\prettytable\prettytable.py", line 986, in header
    self._validate_option("header", val)
  File "c:\Users\Носир\OneDrive\Документы\coding folder\python\git\items_manipulation\item_control_jun\myvenv\lib\site-packages\prettytable\prettytable.py", line 534, in _validate_option
    self._validate_true_or_false(option, val)
  File "c:\Users\Носир\OneDrive\Документы\coding folder\python\git\items_manipulation\item_control_jun\myvenv\lib\site-packages\prettytable\prettytable.py", line 630, in _validate_true_or_false
    raise ValueError(msg)
ValueError: Invalid value for header. Must be True or False.
2024-12-07 01:25:04,104 - ERROR - Error in main: Invalid value for header. Must be True or False.
Traceback (most recent call last):
  File "C:\Users\Носир\OneDrive\Документы\coding folder\python\git\items_manipulation\item_control_jun\myvenv\lib\site-packages\prettytable\prettytable.py", line 627, in _validate_true_or_false
    assert val in (True, False)
AssertionError

During handling of the above exception, another exception occurred:

Traceback (most recent call last):
  File "C:\Users\Носир\OneDrive\Документы\coding folder\python\git\items_manipulation\item_control_jun\logger.py", line 18, in wrapper
    result = func(*args, **kwargs)
  File "C:\Users\Носир\OneDrive\Документы\coding folder\python\git\items_manipulation\item_control_jun\main.py", line 71, in main
    table.header = ('id', 'name', 'slug', 'price', 'is_deleted')
  File "C:\Users\Носир\OneDrive\Документы\coding folder\python\git\items_manipulation\item_control_jun\myvenv\lib\site-packages\prettytable\prettytable.py", line 986, in header
    self._validate_option("header", val)
  File "C:\Users\Носир\OneDrive\Документы\coding folder\python\git\items_manipulation\item_control_jun\myvenv\lib\site-packages\prettytable\prettytable.py", line 534, in _validate_option
    self._validate_true_or_false(option, val)
  File "C:\Users\Носир\OneDrive\Документы\coding folder\python\git\items_manipulation\item_control_jun\myvenv\lib\site-packages\prettytable\prettytable.py", line 630, in _validate_true_or_false
    raise ValueError(msg)
ValueError: Invalid value for header. Must be True or False.
2024-12-07 01:25:40,656 - ERROR - Error in main: can't set attribute 'rows'
Traceback (most recent call last):
  File "C:\Users\Носир\OneDrive\Документы\coding folder\python\git\items_manipulation\item_control_jun\logger.py", line 18, in wrapper
    result = func(*args, **kwargs)
  File "C:\Users\Носир\OneDrive\Документы\coding folder\python\git\items_manipulation\item_control_jun\main.py", line 72, in main
    table.rows = get_all_items()
AttributeError: can't set attribute 'rows'
2024-12-07 01:26:09,192 - ERROR - Error in main: can't set attribute 'rows'
Traceback (most recent call last):
  File "C:\Users\Носир\OneDrive\Документы\coding folder\python\git\items_manipulation\item_control_jun\logger.py", line 18, in wrapper
    result = func(*args, **kwargs)
  File "C:\Users\Носир\OneDrive\Документы\coding folder\python\git\items_manipulation\item_control_jun\main.py", line 73, in main
    table.rows = k
AttributeError: can't set attribute 'rows'
2024-12-07 01:26:44,419 - ERROR - Error in main: can't set attribute 'rows'
Traceback (most recent call last):
  File "C:\Users\Носир\OneDrive\Документы\coding folder\python\git\items_manipulation\item_control_jun\logger.py", line 18, in wrapper
    result = func(*args, **kwargs)
  File "C:\Users\Носир\OneDrive\Документы\coding folder\python\git\items_manipulation\item_control_jun\main.py", line 73, in main
    table.rows = list(k)
AttributeError: can't set attribute 'rows'
2024-12-07 01:53:12,345 - ERROR - Error in connection_db: UNIQUE constraint failed: items.name
Traceback (most recent call last):
  File "C:\Users\Носир\OneDrive\Документы\coding folder\python\git\items_manipulation\item_control_jun\logger.py", line 18, in wrapper
    result = func(*args, **kwargs)
  File "C:\Users\Носир\OneDrive\Документы\coding folder\python\git\items_manipulation\item_control_jun\utils.py", line 23, in connection_db
    result = cursor.execute(query).fetchall()
sqlite3.IntegrityError: UNIQUE constraint failed: items.name
2024-12-07 01:53:12,345 - ERROR - Error in change_item_name_by_name: UNIQUE constraint failed: items.name
Traceback (most recent call last):
  File "C:\Users\Носир\OneDrive\Документы\coding folder\python\git\items_manipulation\item_control_jun\logger.py", line 18, in wrapper
    result = func(*args, **kwargs)
  File "C:\Users\Носир\OneDrive\Документы\coding folder\python\git\items_manipulation\item_control_jun\crud.py", line 48, in change_item_name_by_name
    return connection_db(query)
  File "C:\Users\Носир\OneDrive\Документы\coding folder\python\git\items_manipulation\item_control_jun\logger.py", line 18, in wrapper
    result = func(*args, **kwargs)
  File "C:\Users\Носир\OneDrive\Документы\coding folder\python\git\items_manipulation\item_control_jun\utils.py", line 23, in connection_db
    result = cursor.execute(query).fetchall()
sqlite3.IntegrityError: UNIQUE constraint failed: items.name
2024-12-07 02:02:43,660 - ERROR - Error in main: object of type 'function' has no len()
Traceback (most recent call last):
  File "C:\Users\Носир\OneDrive\Документы\coding folder\python\git\items_manipulation\item_control_jun\logger.py", line 18, in wrapper
    result = func(*args, **kwargs)
  File "C:\Users\Носир\OneDrive\Документы\coding folder\python\git\items_manipulation\item_control_jun\main.py", line 100, in main
    while len(get_item_by_name) == 0:
TypeError: object of type 'function' has no len()
